Workbook
Name _10thCol: #REF!
Name _10thCol: #REF!
Name _2ndCol: #REF!
Name _2ndCol: #REF!
Name _3rdCol: #REF!
Name _3rdCol: #REF!
Name _4thCol: #REF!
Name _4thCol: #REF!
Name _5thCol: #REF!
Name _5thCol: #REF!
Name _6thCol: #REF!
Name _6thCol: #REF!
Name _7thCol: #REF!
Name _7thCol: #REF!
Name _8thCol: #REF!
Name _8thCol: #REF!
Name _9thCol: #REF!
Name _9thCol: #REF!
Name _RWL2: '[1]NIOSH Lifting Equation'!$L$22
Name AM: '[1]NIOSH Lifting Equation'!$H$29
Name AM.1: #REF!
Name AM.1: #REF!
Name AM.10: #REF!
Name AM.10: #REF!
Name AM.2: #REF!
Name AM.2: #REF!
Name AM.3: #REF!
Name AM.3: #REF!
Name AM.4: #REF!
Name AM.4: #REF!
Name AM.5: #REF!
Name AM.5: #REF!
Name AM.6: #REF!
Name AM.6: #REF!
Name AM.7: #REF!
Name AM.7: #REF!
Name AM.8: #REF!
Name AM.8: #REF!
Name AM.9: #REF!
Name AM.9: #REF!
Name AMBIENTAIS: Planilha11!$D$1:$D$10
Name Angle: '[1]NIOSH Lifting Equation'!$D$29
Name Angle1: #REF!
Name Angle1: #REF!
Name Angle10: #REF!
Name Angle10: #REF!
Name Angle2: #REF!
Name Angle2: #REF!
Name Angle3: #REF!
Name Angle3: #REF!
Name Angle4: #REF!
Name Angle4: #REF!
Name Angle5: #REF!
Name Angle5: #REF!
Name Angle6: #REF!
Name Angle6: #REF!
Name Angle7: #REF!
Name Angle7: #REF!
Name Angle8: #REF!
Name Angle8: #REF!

Sheet INCERTEZA
B3: CRÍTICO | C3: CERTA | D3: Controle necessário (P1) | G3: CERTA
B4: CRÍTICO | C4: INCERTA | D4: Controle necessário (P1) Informação adicional necessária [AET] (P1) | G4: INCERTA
B5: CRÍTICO | C5: ALTAMENTE INCERTA | D5: Controle necessário (P1) Informação adicional necessária [AET] (P1) | G5: ALTAMENTE INCERTA
B6: ALTO | C6: CERTA | D6: Controle necessário (P1)
B7: ALTO | C7: INCERTA | D7: Controle necessário (P1) Informação adicional necessária [AET] (P2)
B8: ALTO | C8: ALTAMENTE INCERTA | D8: Controle necessário (P1) Informação adicional necessária [AET] (P1)
B9: MÉDIO | C9: CERTA | D9: Manter o controle existente. (P1) Controle adicional necessário se for possível e viável. (P2)
B10: MÉDIO | C10: INCERTA | D10: Informação adicional necessária [AET] (P2) antes de se decidir se há necessidade de controle adicional .
B11: MÉDIO | C11: ALTAMENTE INCERTA | D11: Informação adicional necessária [AET] (P1) antes de se decidir se há necessidade de controle adicional.
B12: BAIXO | C12: CERTA | D12: Nenhum controle adicional é necessário. Manter o controle existente. (P1)
B13: BAIXO | C13: INCERTA | D13: Informação adicional necessária [AET] (P2)
B14: BAIXO | C14: ALTAMENTE INCERTA | D14: Informação adicional necessária [AET] (P1)
B15: IRRELEVANTE | C15: CERTA | D15: Nenhuma ação é necessária.
B16: IRRELEVANTE | C16: INCERTA | D16: Nenhuma informação adicional é necessária.
B17: IRRELEVANTE | C17: ALTAMENTE INCERTA | D17: Nenhuma informação adicional é necessária.

Sheet AEP
A1: AVALIAÇÃO ERGONÔMICA PRELIMINAR
A4: EMPRESA | Z4: SETOR | AW4: N° pessoas setor/linha | BA4: 8 | BD4: RESPONSÁVEL PELO SETOR | BY4: DATA
A5: UNIDADE | Z5: ATIVIDADE | BD5: RESPONSÁVEL PELA ANÁLISE | BY5: IQCT | CC5: =IF(K9="","-",LANÇAMENTOS!O4) -> - | CF5: =IF(K9="","-",LANÇAMENTOS!P4) -> -
B7: IDENTIFICAÇÃO DO PERIGO | K7: Análise da Atividade | P7: Tipo de Perigo / Fonte(s) de Risco(s) | W7: Fonte Geradora / Circunstâncias | AA7: Tipo de Avaliação | AE7: Referência Utilizada | AI7: N° pessoas envolvidas | AM7: % de Abrangência | AP7: Tempo de exposição | AU7: Gravidade | AZ7: Controle | BF7: RPN [Risk Priority Number] | BI7: Classificação do Risco | BM7: Estimativa da Incerteza | BQ7: CONTROLE | BV7: MONITORAMENTO | BY7: Definições de ações necessárias e prioridades | CT7: Probabilidade
CM8: A | CN8: VA | CO8: E | CP8: Mx | CQ8: Severidade | CT8: G | CV8: C | CZ8: RPN
A9: A | B9: [FOTO] | AM9: =IF(P9="","",AI9/$BA$4) | BF9: =IF(AI9="","",CY9) | BI9: =IF(P9="","",VLOOKUP(BF9,Planilha3!$F$3:$G$18,2,0)) | BQ9: =LANÇAMENTOS!K4 -> - | BV9: =IF(P9="","",LANÇAMENTOS!N4) | CM9: =AM9 | CN9: =IF($CM$9>0.5,4,IF($CM$9>0.25,3,IF($CM$9>0.05,2,1))) -> 4 | CO9: =VLOOKUP(AP9,Planilha2!$C$4:$D$7,2,0) -> #N/A | CP9: =CN9*CO9 -> #N/A | CQ9: =IFERROR(VLOOKUP(CP9,Planilha3!$F$3:$H$18,3,0),"") | CT9: =VLOOKUP(AU9,Planilha2!$C$10:$D$13,2,0) -> #N/A | CV9: =VLOOKUP(AZ9,Planilha2!$E$4:$F$7,2,0) -> #N/A | CW9: =CT9*CV9 -> #N/A | CX9: =VLOOKUP(CW9,Planilha3!$F$3:$H$18,3,0) -> #N/A | CY9: =CO9*CX9 -> #N/A | CZ9: =VLOOKUP(CY9,Planilha3!$F$3:$H$18,3,0) -> #N/A
A10: B | B10: [FOTO] | AM10: =IF(P10="","",AI10/$BA$4) | BF10: =IF(AI10="","",CY10) | BI10: =IF(P10="","",VLOOKUP(BF10,Planilha3!$F$3:$G$18,2,0)) | BQ10: =LANÇAMENTOS!K5 -> - | BV10: =IF(P10="","",LANÇAMENTOS!N5) | CM10: =AM10 | CN10: =IF($CM$9>0.5,4,IF($CM$9>0.25,3,IF($CM$9>0.05,2,1))) -> 4 | CO10: =VLOOKUP(AP10,Planilha2!$C$4:$D$7,2,0) -> #N/A | CP10: =CN10*CO10 -> #N/A | CQ10: =IFERROR(VLOOKUP(CP10,Planilha3!$F$3:$H$18,3,0),"") | CT10: =VLOOKUP(AU10,Planilha2!$C$10:$D$13,2,0) -> #N/A | CV10: =VLOOKUP(AZ10,Planilha2!$E$4:$F$7,2,0) -> #N/A | CW10: =CT10*CV10 -> #N/A | CX10: =VLOOKUP(CW10,Planilha3!$F$3:$H$18,3,0) -> #N/A | CY10: =CO10*CX10 -> #N/A | CZ10: =VLOOKUP(CY10,Planilha3!$F$3:$H$18,3,0) -> #N/A
A11: C | B11: [FOTO] | AM11: =IF(P11="","",AI11/$BA$4) | BF11: =IF(AI11="","",CY11) | BI11: =IF(P11="","",VLOOKUP(BF11,Planilha3!$F$3:$G$18,2,0)) | BQ11: =LANÇAMENTOS!K6 -> - | BV11: =IF(P11="","",LANÇAMENTOS!N6) | CM11: =AM11 | CN11: =IF($CM$9>0.5,4,IF($CM$9>0.25,3,IF($CM$9>0.05,2,1))) -> 4 | CO11: =VLOOKUP(AP11,Planilha2!$C$4:$D$7,2,0) -> #N/A | CP11: =CN11*CO11 -> #N/A | CQ11: =IFERROR(VLOOKUP(CP11,Planilha3!$F$3:$H$18,3,0),"") | CT11: =VLOOKUP(AU11,Planilha2!$C$10:$D$13,2,0) -> #N/A | CV11: =VLOOKUP(AZ11,Planilha2!$E$4:$F$7,2,0) -> #N/A | CW11: =CT11*CV11 -> #N/A | CX11: =VLOOKUP(CW11,Planilha3!$F$3:$H$18,3,0) -> #N/A | CY11: =CO11*CX11 -> #N/A | CZ11: =VLOOKUP(CY11,Planilha3!$F$3:$H$18,3,0) -> #N/A
A12: D | B12: [FOTO] | AM12: =IF(P12="","",AI12/$BA$4) | BF12: =IF(AI12="","",CY12) | BI12: =IF(P12="","",VLOOKUP(BF12,Planilha3!$F$3:$G$18,2,0)) | BQ12: =LANÇAMENTOS!K7 -> - | BV12: =IF(P12="","",LANÇAMENTOS!N7) | CM12: =AM12 | CN12: =IF($CM$9>0.5,4,IF($CM$9>0.25,3,IF($CM$9>0.05,2,1))) -> 4 | CO12: =VLOOKUP(AP12,Planilha2!$C$4:$D$7,2,0) -> #N/A | CP12: =CN12*CO12 -> #N/A | CQ12: =IFERROR(VLOOKUP(CP12,Planilha3!$F$3:$H$18,3,0),"") | CT12: =VLOOKUP(AU12,Planilha2!$C$10:$D$13,2,0) -> #N/A | CV12: =VLOOKUP(AZ12,Planilha2!$E$4:$F$7,2,0) -> #N/A | CW12: =CT12*CV12 -> #N/A | CX12: =VLOOKUP(CW12,Planilha3!$F$3:$H$18,3,0) -> #N/A | CY12: =CO12*CX12 -> #N/A | CZ12: =VLOOKUP(CY12,Planilha3!$F$3:$H$18,3,0) -> #N/A
A13: E | B13: [FOTO] | AM13: =IF(P13="","",AI13/$BA$4) | BF13: =IF(AI13="","",CY13) | BI13: =IF(P13="","",VLOOKUP(BF13,Planilha3!$F$3:$G$18,2,0)) | BQ13: =LANÇAMENTOS!K8 -> - | BV13: =IF(P13="","",LANÇAMENTOS!N8) | CM13: =AM13 | CN13: =IF($CM$9>0.5,4,IF($CM$9>0.25,3,IF($CM$9>0.05,2,1))) -> 4 | CO13: =VLOOKUP(AP13,Planilha2!$C$4:$D$7,2,0) -> #N/A | CP13: =CN13*CO13 -> #N/A | CQ13: =IFERROR(VLOOKUP(CP13,Planilha3!$F$3:$H$18,3,0),"") | CT13: =VLOOKUP(AU13,Planilha2!$C$10:$D$13,2,0) -> #N/A | CV13: =VLOOKUP(AZ13,Planilha2!$E$4:$F$7,2,0) -> #N/A | CW13: =CT13*CV13 -> #N/A | CX13: =VLOOKUP(CW13,Planilha3!$F$3:$H$18,3,0) -> #N/A | CY13: =CO13*CX13 -> #N/A | CZ13: =VLOOKUP(CY13,Planilha3!$F$3:$H$18,3,0) -> #N/A
A14: F | B14: [FOTO] | AM14: =IF(P14="","",AI14/$BA$4) | BF14: =IF(AI14="","",CY14) | BI14: =IF(P14="","",VLOOKUP(BF14,Planilha3!$F$3:$G$18,2,0)) | BQ14: =LANÇAMENTOS!K9 -> - | BV14: =IF(P14="","",LANÇAMENTOS!N9) | CM14: =AM14 | CN14: =IF($CM$9>0.5,4,IF($CM$9>0.25,3,IF($CM$9>0.05,2,1))) -> 4 | CO14: =VLOOKUP(AP14,Planilha2!$C$4:$D$7,2,0) -> #N/A | CP14: =CN14*CO14 -> #N/A | CQ14: =IFERROR(VLOOKUP(CP14,Planilha3!$F$3:$H$18,3,0),"") | CT14: =VLOOKUP(AU14,Planilha2!$C$10:$D$13,2,0) -> #N/A | CV14: =VLOOKUP(AZ14,Planilha2!$E$4:$F$7,2,0) -> #N/A | CW14: =CT14*CV14 -> #N/A | CX14: =VLOOKUP(CW14,Planilha3!$F$3:$H$18,3,0) -> #N/A | CY14: =CO14*CX14 -> #N/A | CZ14: =VLOOKUP(CY14,Planilha3!$F$3:$H$18,3,0) -> #N/A
A15: G | B15: [FOTO] | AM15: =IF(P15="","",AI15/$BA$4) | BF15: =IF(AI15="","",CY15) | BI15: =IF(P15="","",VLOOKUP(BF15,Planilha3!$F$3:$G$18,2,0)) | BQ15: =LANÇAMENTOS!K10 -> - | BV15: =IF(P15="","",LANÇAMENTOS!N10) | CM15: =AM15 | CN15: =IF($CM$9>0.5,4,IF($CM$9>0.25,3,IF($CM$9>0.05,2,1))) -> 4 | CO15: =VLOOKUP(AP15,Planilha2!$C$4:$D$7,2,0) -> #N/A | CP15: =CN15*CO15 -> #N/A | CQ15: =IFERROR(VLOOKUP(CP15,Planilha3!$F$3:$H$18,3,0),"") | CT15: =VLOOKUP(AU15,Planilha2!$C$10:$D$13,2,0) -> #N/A | CV15: =VLOOKUP(AZ15,Planilha2!$E$4:$F$7,2,0) -> #N/A | CW15: =CT15*CV15 -> #N/A | CX15: =VLOOKUP(CW15,Planilha3!$F$3:$H$18,3,0) -> #N/A | CY15: =CO15*CX15 -> #N/A | CZ15: =VLOOKUP(CY15,Planilha3!$F$3:$H$18,3,0) -> #N/A
A16: H | B16: [FOTO] | AM16: =IF(P16="","",AI16/$BA$4) | BF16: =IF(AI16="","",CY16) | BI16: =IF(P16="","",VLOOKUP(BF16,Planilha3!$F$3:$G$18,2,0)) | BQ16: =LANÇAMENTOS!K11 -> - | BV16: =IF(P16="","",LANÇAMENTOS!N11) | CM16: =AM16 | CN16: =IF($CM$9>0.5,4,IF($CM$9>0.25,3,IF($CM$9>0.05,2,1))) -> 4 | CO16: =VLOOKUP(AP16,Planilha2!$C$4:$D$7,2,0) -> #N/A | CP16: =CN16*CO16 -> #N/A | CQ16: =IFERROR(VLOOKUP(CP16,Planilha3!$F$3:$H$18,3,0),"") | CT16: =VLOOKUP(AU16,Planilha2!$C$10:$D$13,2,0) -> #N/A | CV16: =VLOOKUP(AZ16,Planilha2!$E$4:$F$7,2,0) -> #N/A | CW16: =CT16*CV16 -> #N/A | CX16: =VLOOKUP(CW16,Planilha3!$F$3:$H$18,3,0) -> #N/A | CY16: =CO16*CX16 -> #N/A | CZ16: =VLOOKUP(CY16,Planilha3!$F$3:$H$18,3,0) -> #N/A
A17: I | B17: [FOTO] | AM17: =IF(P17="","",AI17/$BA$4) | BF17: =IF(AI17="","",CY17) | BI17: =IF(P17="","",VLOOKUP(BF17,Planilha3!$F$3:$G$18,2,0)) | BQ17: =LANÇAMENTOS!K12 -> - | BV17: =IF(P17="","",LANÇAMENTOS!N12) | CM17: =AM17 | CN17: =IF($CM$9>0.5,4,IF($CM$9>0.25,3,IF($CM$9>0.05,2,1))) -> 4 | CO17: =VLOOKUP(AP17,Planilha2!$C$4:$D$7,2,0) -> #N/A | CP17: =CN17*CO17 -> #N/A | CQ17: =IFERROR(VLOOKUP(CP17,Planilha3!$F$3:$H$18,3,0),"") | CT17: =VLOOKUP(AU17,Planilha2!$C$10:$D$13,2,0) -> #N/A | CV17: =VLOOKUP(AZ17,Planilha2!$E$4:$F$7,2,0) -> #N/A | CW17: =CT17*CV17 -> #N/A | CX17: =VLOOKUP(CW17,Planilha3!$F$3:$H$18,3,0) -> #N/A | CY17: =CO17*CX17 -> #N/A | CZ17: =VLOOKUP(CY17,Planilha3!$F$3:$H$18,3,0) -> #N/A
A18: J | B18: [FOTO] | AM18: =IF(P18="","",AI18/$BA$4) | BF18: =IF(AI18="","",CY18) | BI18: =IF(P18="","",VLOOKUP(BF18,Planilha3!$F$3:$G$18,2,0)) | BQ18: =LANÇAMENTOS!K13 -> - | BV18: =IF(P18="","",LANÇAMENTOS!N13) | CM18: =AM18 | CN18: =IF($CM$9>0.5,4,IF($CM$9>0.25,3,IF($CM$9>0.05,2,1))) -> 4 | CO18: =VLOOKUP(AP18,Planilha2!$C$4:$D$7,2,0) -> #N/A | CP18: =CN18*CO18 -> #N/A | CQ18: =IFERROR(VLOOKUP(CP18,Planilha3!$F$3:$H$18,3,0),"") | CT18: =VLOOKUP(AU18,Planilha2!$C$10:$D$13,2,0) -> #N/A | CV18: =VLOOKUP(AZ18,Planilha2!$E$4:$F$7,2,0) -> #N/A | CW18: =CT18*CV18 -> #N/A | CX18: =VLOOKUP(CW18,Planilha3!$F$3:$H$18,3,0) -> #N/A | CY18: =CO18*CX18 -> #N/A | CZ18: =VLOOKUP(CY18,Planilha3!$F$3:$H$18,3,0) -> #N/A
A19: K | AM19: =IF(P19="","",AI19/$BA$4) | BF19: =IF(AI19="","",CY19) | BI19: =IF(P19="","",VLOOKUP(BF19,Planilha3!$F$3:$G$18,2,0)) | BQ19: =LANÇAMENTOS!K14 -> - | BV19: =IF(P19="","",LANÇAMENTOS!N14) | CM19: =AM19 | CN19: =IF($CM$9>0.5,4,IF($CM$9>0.25,3,IF($CM$9>0.05,2,1))) -> 4 | CO19: =VLOOKUP(AP19,Planilha2!$C$4:$D$7,2,0) -> #N/A | CP19: =CN19*CO19 -> #N/A | CQ19: =IFERROR(VLOOKUP(CP19,Planilha3!$F$3:$H$18,3,0),"") | CT19: =VLOOKUP(AU19,Planilha2!$C$10:$D$13,2,0) -> #N/A | CV19: =VLOOKUP(AZ19,Planilha2!$E$4:$F$7,2,0) -> #N/A | CW19: =CT19*CV19 -> #N/A | CX19: =VLOOKUP(CW19,Planilha3!$F$3:$H$18,3,0) -> #N/A | CY19: =CO19*CX19 -> #N/A | CZ19: =VLOOKUP(CY19,Planilha3!$F$3:$H$18,3,0) -> #N/A
A20: L | B20: N/A | AM20: =IF(P20="","",AI20/$BA$4) | BF20: =IF(AI20="","",CY20) | BI20: =IF(P20="","",VLOOKUP(BF20,Planilha3!$F$3:$G$18,2,0)) | BQ20: =LANÇAMENTOS!K15 -> - | BV20: =IF(P20="","",LANÇAMENTOS!N15) | CM20: =AM20 | CN20: =IF($CM$9>0.5,4,IF($CM$9>0.25,3,IF($CM$9>0.05,2,1))) -> 4 | CO20: =VLOOKUP(AP20,Planilha2!$C$4:$D$7,2,0) -> #N/A | CP20: =CN20*CO20 -> #N/A | CQ20: =IFERROR(VLOOKUP(CP20,Planilha3!$F$3:$H$18,3,0),"") | CT20: =VLOOKUP(AU20,Planilha2!$C$10:$D$13,2,0) -> #N/A | CV20: =VLOOKUP(AZ20,Planilha2!$E$4:$F$7,2,0) -> #N/A | CW20: =CT20*CV20 -> #N/A | CX20: =VLOOKUP(CW20,Planilha3!$F$3:$H$18,3,0) -> #N/A | CY20: =CO20*CX20 -> #N/A | CZ20: =VLOOKUP(CY20,Planilha3!$F$3:$H$18,3,0) -> #N/A
A21: M | B21: N/A | AM21: =IF(P21="","",AI21/$BA$4) | BF21: =IF(AI21="","",CY21) | BI21: =IF(P21="","",VLOOKUP(BF21,Planilha3!$F$3:$G$18,2,0)) | BQ21: =LANÇAMENTOS!K16 -> - | BV21: =IF(P21="","",LANÇAMENTOS!N16) | CM21: =AM21 | CN21: =IF($CM$9>0.5,4,IF($CM$9>0.25,3,IF($CM$9>0.05,2,1))) -> 4 | CO21: =VLOOKUP(AP21,Planilha2!$C$4:$D$7,2,0) -> #N/A | CP21: =CN21*CO21 -> #N/A | CQ21: =IFERROR(VLOOKUP(CP21,Planilha3!$F$3:$H$18,3,0),"") | CT21: =VLOOKUP(AU21,Planilha2!$C$10:$D$13,2,0) -> #N/A | CV21: =VLOOKUP(AZ21,Planilha2!$E$4:$F$7,2,0) -> #N/A | CW21: =CT21*CV21 -> #N/A | CX21: =VLOOKUP(CW21,Planilha3!$F$3:$H$18,3,0) -> #N/A | CY21: =CO21*CX21 -> #N/A | CZ21: =VLOOKUP(CY21,Planilha3!$F$3:$H$18,3,0) -> #N/A
A22: N | AM22: =IF(P22="","",AI22/$BA$4) | BF22: =IF(AI22="","",CY22) | BI22: =IF(P22="","",VLOOKUP(BF22,Planilha3!$F$3:$G$18,2,0)) | BQ22: =LANÇAMENTOS!K17 -> - | BV22: =IF(P22="","",LANÇAMENTOS!N17) | CM22: =AM22 | CN22: =IF($CM$9>0.5,4,IF($CM$9>0.25,3,IF($CM$9>0.05,2,1))) -> 4 | CO22: =VLOOKUP(AP22,Planilha2!$C$4:$D$7,2,0) -> #N/A | CP22: =CN22*CO22 -> #N/A | CQ22: =IFERROR(VLOOKUP(CP22,Planilha3!$F$3:$H$18,3,0),"") | CT22: =VLOOKUP(AU22,Planilha2!$C$10:$D$13,2,0) -> #N/A | CV22: =VLOOKUP(AZ22,Planilha2!$E$4:$F$7,2,0) -> #N/A | CW22: =CT22*CV22 -> #N/A | CX22: =VLOOKUP(CW22,Planilha3!$F$3:$H$18,3,0) -> #N/A | CY22: =CO22*CX22 -> #N/A | CZ22: =VLOOKUP(CY22,Planilha3!$F$3:$H$18,3,0) -> #N/A
A23: O | AM23: =IF(P23="","",AI23/$BA$4) | BF23: =IF(AI23="","",CY23) | BI23: =IF(P23="","",VLOOKUP(BF23,Planilha3!$F$3:$G$18,2,0)) | BQ23: =LANÇAMENTOS!K18 -> - | BV23: =IF(P23="","",LANÇAMENTOS!N18) | CM23: =AM23 | CN23: =IF($CM$9>0.5,4,IF($CM$9>0.25,3,IF($CM$9>0.05,2,1))) -> 4 | CO23: =VLOOKUP(AP23,Planilha2!$C$4:$D$7,2,0) -> #N/A | CP23: =CN23*CO23 -> #N/A | CQ23: =IFERROR(VLOOKUP(CP23,Planilha3!$F$3:$H$18,3,0),"") | CT23: =VLOOKUP(AU23,Planilha2!$C$10:$D$13,2,0) -> #N/A | CV23: =VLOOKUP(AZ23,Planilha2!$E$4:$F$7,2,0) -> #N/A | CW23: =CT23*CV23 -> #N/A | CX23: =VLOOKUP(CW23,Planilha3!$F$3:$H$18,3,0) -> #N/A | CY23: =CO23*CX23 -> #N/A | CZ23: =VLOOKUP(CY23,Planilha3!$F$3:$H$18,3,0) -> #N/A
A24: P | AM24: =IF(P24="","",AI24/$BA$4) | BF24: =IF(AI24="","",CY24) | BI24: =IF(P24="","",VLOOKUP(BF24,Planilha3!$F$3:$G$18,2,0)) | BQ24: =LANÇAMENTOS!K19 -> - | BV24: =IF(P24="","",LANÇAMENTOS!N19) | CM24: =AM24 | CN24: =IF($CM$9>0.5,4,IF($CM$9>0.25,3,IF($CM$9>0.05,2,1))) -> 4 | CO24: =VLOOKUP(AP24,Planilha2!$C$4:$D$7,2,0) -> #N/A | CP24: =CN24*CO24 -> #N/A | CQ24: =IFERROR(VLOOKUP(CP24,Planilha3!$F$3:$H$18,3,0),"") | CT24: =VLOOKUP(AU24,Planilha2!$C$10:$D$13,2,0) -> #N/A | CV24: =VLOOKUP(AZ24,Planilha2!$E$4:$F$7,2,0) -> #N/A | CW24: =CT24*CV24 -> #N/A | CX24: =VLOOKUP(CW24,Planilha3!$F$3:$H$18,3,0) -> #N/A | CY24: =CO24*CX24 -> #N/A | CZ24: =VLOOKUP(CY24,Planilha3!$F$3:$H$18,3,0) -> #N/A
A25: Q | AM25: =IF(P25="","",AI25/$BA$4) | BF25: =IF(AI25="","",CY25) | BI25: =IF(P25="","",VLOOKUP(BF25,Planilha3!$F$3:$G$18,2,0)) | BQ25: =LANÇAMENTOS!K20 -> - | BV25: =IF(P25="","",LANÇAMENTOS!N20) | CM25: =AM25 | CN25: =IF($CM$9>0.5,4,IF($CM$9>0.25,3,IF($CM$9>0.05,2,1))) -> 4 | CO25: =VLOOKUP(AP25,Planilha2!$C$4:$D$7,2,0) -> #N/A | CP25: =CN25*CO25 -> #N/A | CQ25: =IFERROR(VLOOKUP(CP25,Planilha3!$F$3:$H$18,3,0),"") | CT25: =VLOOKUP(AU25,Planilha2!$C$10:$D$13,2,0) -> #N/A | CV25: =VLOOKUP(AZ25,Planilha2!$E$4:$F$7,2,0) -> #N/A | CW25: =CT25*CV25 -> #N/A | CX25: =VLOOKUP(CW25,Planilha3!$F$3:$H$18,3,0) -> #N/A | CY25: =CO25*CX25 -> #N/A | CZ25: =VLOOKUP(CY25,Planilha3!$F$3:$H$18,3,0) -> #N/A
A26: R | AM26: =IF(P26="","",AI26/$BA$4) | BF26: =IF(AI26="","",CY26) | BI26: =IF(P26="","",VLOOKUP(BF26,Planilha3!$F$3:$G$18,2,0)) | BQ26: =LANÇAMENTOS!K21 -> - | BV26: =IF(P26="","",LANÇAMENTOS!N21) | CM26: =AM26 | CN26: =IF($CM$9>0.5,4,IF($CM$9>0.25,3,IF($CM$9>0.05,2,1))) -> 4 | CO26: =VLOOKUP(AP26,Planilha2!$C$4:$D$7,2,0) -> #N/A | CP26: =CN26*CO26 -> #N/A | CQ26: =IFERROR(VLOOKUP(CP26,Planilha3!$F$3:$H$18,3,0),"") | CT26: =VLOOKUP(AU26,Planilha2!$C$10:$D$13,2,0) -> #N/A | CV26: =VLOOKUP(AZ26,Planilha2!$E$4:$F$7,2,0) -> #N/A | CW26: =CT26*CV26 -> #N/A | CX26: =VLOOKUP(CW26,Planilha3!$F$3:$H$18,3,0) -> #N/A | CY26: =CO26*CX26 -> #N/A | CZ26: =VLOOKUP(CY26,Planilha3!$F$3:$H$18,3,0) -> #N/A

Sheet LANÇAMENTOS
H2: GRAU DE RISCO PONDERADO | J2: INCERTEZA | L2: MONITORAMENTO
A3: Agente | Tipo | B3: Tipo de Perigo / Fonte(s) de Risco(s) | C3: Consequências / Impacto / Agravos à Saúde | D3: Critérios Adotados para Avaliação dos Riscos | E3: Fonte Geradora / Circunstâncias | H3: RPN | I3: QUALIFICAÇÃO | J3: ESTIMATIVA | K3: CONTROLE | L3: PROBABILIDADE | M3: GRAVIDADE | N3: QUALIFICAÇÃO | O3: IQCT Indicador da Qualidade das Condições de Trabalho | W3: MÍNIMO | X3: 25
A4: ERGONÔMICO | B4: Dispositivos que dificultam a postura ereta | C4: Grupo XIII da CID-10 | D4: SOBANE/DEPARIS | E4: Mobiliário sem meios de regulagem de ajuste | H4: =AEP!BF9 | I4: =AEP!BI9 | J4: =AEP!BM9 -> 0 | K4: =IF(AND(I4=INCERTEZA!$B$3,J4=INCERTEZA!$C$3),INCERTEZA!$D$3,IF(AND(I4=INCERTEZA!$B$4,J4=INCERTEZA!$C$4),INCERTEZA!$D$4,IF(AND(I4=INCERTEZA!$B$5,J4=INCERTEZA!$C$5),INCERTEZA!$D$5,IF(AND(I4=INCERTEZA!$B$6,J4=INCERTEZA!$C$6),INCERTEZA!$D$6,IF(AND(I4=INCERTEZA!$B$7,J4=INCERTEZA!$C$7),INCERTEZA!$D$7,IF(AND(I4=INCERTEZA!$B$8,J4=INCERTEZA!$C$8),INCERTEZA!$D$8,IF(AND(I4=INCERTEZA!$B$9,J4=INCERTEZA!$C$9),INCERTEZA!$D$9,IF(AND(I4=INCERTEZA!$B$10,J4=INCERTEZA!$C$10),INCERTEZA!$D$10,IF(AND(I4=INCERTEZA!$B$11,J4=INCERTEZA!$C$11),INCERTEZA!$D$11,IF(AND(I4=INCERTEZA!$B$12,J4=INCERTEZA!$C$12),INCERTEZA!$D$12,IF(AND(I4=INCERTEZA!$B$13,J4=INCERTEZA!$C$13),INCERTEZA!$D$13,IF(AND(I4=INCERTEZA!$B$14,J4=INCERTEZA!$C$14),INCERTEZA!$D$14,IF(AND(I4=INCERTEZA!$B$15,J4=INCERTEZA!$C$15),INCERTEZA!$D$15,IF(AND(I4=INCERTEZA!$B$16,J4=INCERTEZA!$C$16),INCERTEZA!$D$16,IF(AND(I4=INCERTEZA!$B$17,J4=INCERTEZA!$C$17),INCERTEZA!$D$17,"-"))))))))))))))) -> - | L4: =AEP!CX9 -> #N/A | M4: =AEP!CO9 -> #N/A | N4: =IF(AND(L4=monitoramento!$C$4,M4=monitoramento!$D$4),monitoramento!$E$4,IF(AND(L4=monitoramento!$C$5,M4=monitoramento!$D$5),monitoramento!$E$5,IF(AND(L4=monitoramento!$C$6,M4=monitoramento!$D$6),monitoramento!$E$6,IF(AND(L4=monitoramento!$C$7,M4=monitoramento!$D$7),monitoramento!$E$7,IF(AND(L4=monitoramento!$C$8,M4=monitoramento!$D$8),monitoramento!$E$8,IF(AND(L4=monitoramento!$C$9,M4=monitoramento!$D$9),monitoramento!$E$9,IF(AND(L4=monitoramento!$C$10,M4=monitoramento!$D$10),monitoramento!$E$10,IF(AND(L4=monitoramento!$C$11,M4=monitoramento!$D$11),monitoramento!$E$11,IF(AND(L4=monitoramento!$C$12,M4=monitoramento!$D$12),monitoramento!$E$12,IF(AND(L4=monitoramento!$C$13,M4=monitoramento!$D$13),monitoramento!$E$13,IF(AND(L4=monitoramento!$C$14,M4=monitoramento!$D$14),monitoramento!$E$14,IF(AND(L4=monitoramento!$C$15,M4=monitoramento!$D$15),monitoramento!$E$15,IF(AND(L4=monitoramento!$C$16,M4=monitoramento!$D$16),monitoramento!$E$16,IF(AND(L4=monitoramento!$C$17,M4=monitoramento!$D$17),monitoramento!$E$17,IF(AND(L4=monitoramento!$C$18,M4=monitoramento!$D$18),monitoramento!$E$18,IF(AND(L4=monitoramento!$C$19,M4=monitoramento!$D$19),monitoramento!$E$19)))))))))))))))) -> #N/A | O4: =U7/T7 -> #DIV/0! | P4: =IF(Y5>=50,"BOA",IF(Y5>25,"REGULAR",IF(Y5<25,"RUIM"))) -> #DIV/0! | S4: BAIXO | T4: =COUNTIF(I:I,S4) -> 0 | U4: =T4*4 -> 0 | W4: IDEAL | X4: 100
H5: =AEP!BF10 | I5: =AEP!BI10 | J5: =AEP!BM10 -> 0 | K5: =IF(AND(I5=INCERTEZA!$B$3,J5=INCERTEZA!$C$3),INCERTEZA!$D$3,IF(AND(I5=INCERTEZA!$B$4,J5=INCERTEZA!$C$4),INCERTEZA!$D$4,IF(AND(I5=INCERTEZA!$B$5,J5=INCERTEZA!$C$5),INCERTEZA!$D$5,IF(AND(I5=INCERTEZA!$B$6,J5=INCERTEZA!$C$6),INCERTEZA!$D$6,IF(AND(I5=INCERTEZA!$B$7,J5=INCERTEZA!$C$7),INCERTEZA!$D$7,IF(AND(I5=INCERTEZA!$B$8,J5=INCERTEZA!$C$8),INCERTEZA!$D$8,IF(AND(I5=INCERTEZA!$B$9,J5=INCERTEZA!$C$9),INCERTEZA!$D$9,IF(AND(I5=INCERTEZA!$B$10,J5=INCERTEZA!$C$10),INCERTEZA!$D$10,IF(AND(I5=INCERTEZA!$B$11,J5=INCERTEZA!$C$11),INCERTEZA!$D$11,IF(AND(I5=INCERTEZA!$B$12,J5=INCERTEZA!$C$12),INCERTEZA!$D$12,IF(AND(I5=INCERTEZA!$B$13,J5=INCERTEZA!$C$13),INCERTEZA!$D$13,IF(AND(I5=INCERTEZA!$B$14,J5=INCERTEZA!$C$14),INCERTEZA!$D$14,IF(AND(I5=INCERTEZA!$B$15,J5=INCERTEZA!$C$15),INCERTEZA!$D$15,IF(AND(I5=INCERTEZA!$B$16,J5=INCERTEZA!$C$16),INCERTEZA!$D$16,IF(AND(I5=INCERTEZA!$B$17,J5=INCERTEZA!$C$17),INCERTEZA!$D$17,"-"))))))))))))))) -> - | L5: =AEP!CX10 -> #N/A | M5: =AEP!CO10 -> #N/A | N5: =IF(AND(L5=monitoramento!$C$4,M5=monitoramento!$D$4),monitoramento!$E$4,IF(AND(L5=monitoramento!$C$5,M5=monitoramento!$D$5),monitoramento!$E$5,IF(AND(L5=monitoramento!$C$6,M5=monitoramento!$D$6),monitoramento!$E$6,IF(AND(L5=monitoramento!$C$7,M5=monitoramento!$D$7),monitoramento!$E$7,IF(AND(L5=monitoramento!$C$8,M5=monitoramento!$D$8),monitoramento!$E$8,IF(AND(L5=monitoramento!$C$9,M5=monitoramento!$D$9),monitoramento!$E$9,IF(AND(L5=monitoramento!$C$10,M5=monitoramento!$D$10),monitoramento!$E$10,IF(AND(L5=monitoramento!$C$11,M5=monitoramento!$D$11),monitoramento!$E$11,IF(AND(L5=monitoramento!$C$12,M5=monitoramento!$D$12),monitoramento!$E$12,IF(AND(L5=monitoramento!$C$13,M5=monitoramento!$D$13),monitoramento!$E$13,IF(AND(L5=monitoramento!$C$14,M5=monitoramento!$D$14),monitoramento!$E$14,IF(AND(L5=monitoramento!$C$15,M5=monitoramento!$D$15),monitoramento!$E$15,IF(AND(L5=monitoramento!$C$16,M5=monitoramento!$D$16),monitoramento!$E$16,IF(AND(L5=monitoramento!$C$17,M5=monitoramento!$D$17),monitoramento!$E$17,IF(AND(L5=monitoramento!$C$18,M5=monitoramento!$D$18),monitoramento!$E$18,IF(AND(L5=monitoramento!$C$19,M5=monitoramento!$D$19),monitoramento!$E$19)))))))))))))))) -> #N/A | S5: MÉDIO | T5: =COUNTIF(I:I,S5) -> 0 | U5: =T5*3 -> 0 | W5: ENCONTRADO | X5: =O4*100 -> #DIV/0! | Y5: =(100/(X4-X3))*(X5-X3) -> #DIV/0!
H6: =AEP!BF11 | I6: =AEP!BI11 | J6: =AEP!BM11 -> 0 | K6: =IF(AND(I6=INCERTEZA!$B$3,J6=INCERTEZA!$C$3),INCERTEZA!$D$3,IF(AND(I6=INCERTEZA!$B$4,J6=INCERTEZA!$C$4),INCERTEZA!$D$4,IF(AND(I6=INCERTEZA!$B$5,J6=INCERTEZA!$C$5),INCERTEZA!$D$5,IF(AND(I6=INCERTEZA!$B$6,J6=INCERTEZA!$C$6),INCERTEZA!$D$6,IF(AND(I6=INCERTEZA!$B$7,J6=INCERTEZA!$C$7),INCERTEZA!$D$7,IF(AND(I6=INCERTEZA!$B$8,J6=INCERTEZA!$C$8),INCERTEZA!$D$8,IF(AND(I6=INCERTEZA!$B$9,J6=INCERTEZA!$C$9),INCERTEZA!$D$9,IF(AND(I6=INCERTEZA!$B$10,J6=INCERTEZA!$C$10),INCERTEZA!$D$10,IF(AND(I6=INCERTEZA!$B$11,J6=INCERTEZA!$C$11),INCERTEZA!$D$11,IF(AND(I6=INCERTEZA!$B$12,J6=INCERTEZA!$C$12),INCERTEZA!$D$12,IF(AND(I6=INCERTEZA!$B$13,J6=INCERTEZA!$C$13),INCERTEZA!$D$13,IF(AND(I6=INCERTEZA!$B$14,J6=INCERTEZA!$C$14),INCERTEZA!$D$14,IF(AND(I6=INCERTEZA!$B$15,J6=INCERTEZA!$C$15),INCERTEZA!$D$15,IF(AND(I6=INCERTEZA!$B$16,J6=INCERTEZA!$C$16),INCERTEZA!$D$16,IF(AND(I6=INCERTEZA!$B$17,J6=INCERTEZA!$C$17),INCERTEZA!$D$17,"-"))))))))))))))) -> - | L6: =AEP!CX11 -> #N/A | M6: =AEP!CO11 -> #N/A | N6: =IF(AND(L6=monitoramento!$C$4,M6=monitoramento!$D$4),monitoramento!$E$4,IF(AND(L6=monitoramento!$C$5,M6=monitoramento!$D$5),monitoramento!$E$5,IF(AND(L6=monitoramento!$C$6,M6=monitoramento!$D$6),monitoramento!$E$6,IF(AND(L6=monitoramento!$C$7,M6=monitoramento!$D$7),monitoramento!$E$7,IF(AND(L6=monitoramento!$C$8,M6=monitoramento!$D$8),monitoramento!$E$8,IF(AND(L6=monitoramento!$C$9,M6=monitoramento!$D$9),monitoramento!$E$9,IF(AND(L6=monitoramento!$C$10,M6=monitoramento!$D$10),monitoramento!$E$10,IF(AND(L6=monitoramento!$C$11,M6=monitoramento!$D$11),monitoramento!$E$11,IF(AND(L6=monitoramento!$C$12,M6=monitoramento!$D$12),monitoramento!$E$12,IF(AND(L6=monitoramento!$C$13,M6=monitoramento!$D$13),monitoramento!$E$13,IF(AND(L6=monitoramento!$C$14,M6=monitoramento!$D$14),monitoramento!$E$14,IF(AND(L6=monitoramento!$C$15,M6=monitoramento!$D$15),monitoramento!$E$15,IF(AND(L6=monitoramento!$C$16,M6=monitoramento!$D$16),monitoramento!$E$16,IF(AND(L6=monitoramento!$C$17,M6=monitoramento!$D$17),monitoramento!$E$17,IF(AND(L6=monitoramento!$C$18,M6=monitoramento!$D$18),monitoramento!$E$18,IF(AND(L6=monitoramento!$C$19,M6=monitoramento!$D$19),monitoramento!$E$19)))))))))))))))) -> #N/A | S6: ALTO | T6: =COUNTIF(I:I,S6) -> 0 | U6: =T6*1 -> 0
H7: =AEP!BF12 | I7: =AEP!BI12 | J7: =AEP!BM12 -> 0 | K7: =IF(AND(I7=INCERTEZA!$B$3,J7=INCERTEZA!$C$3),INCERTEZA!$D$3,IF(AND(I7=INCERTEZA!$B$4,J7=INCERTEZA!$C$4),INCERTEZA!$D$4,IF(AND(I7=INCERTEZA!$B$5,J7=INCERTEZA!$C$5),INCERTEZA!$D$5,IF(AND(I7=INCERTEZA!$B$6,J7=INCERTEZA!$C$6),INCERTEZA!$D$6,IF(AND(I7=INCERTEZA!$B$7,J7=INCERTEZA!$C$7),INCERTEZA!$D$7,IF(AND(I7=INCERTEZA!$B$8,J7=INCERTEZA!$C$8),INCERTEZA!$D$8,IF(AND(I7=INCERTEZA!$B$9,J7=INCERTEZA!$C$9),INCERTEZA!$D$9,IF(AND(I7=INCERTEZA!$B$10,J7=INCERTEZA!$C$10),INCERTEZA!$D$10,IF(AND(I7=INCERTEZA!$B$11,J7=INCERTEZA!$C$11),INCERTEZA!$D$11,IF(AND(I7=INCERTEZA!$B$12,J7=INCERTEZA!$C$12),INCERTEZA!$D$12,IF(AND(I7=INCERTEZA!$B$13,J7=INCERTEZA!$C$13),INCERTEZA!$D$13,IF(AND(I7=INCERTEZA!$B$14,J7=INCERTEZA!$C$14),INCERTEZA!$D$14,IF(AND(I7=INCERTEZA!$B$15,J7=INCERTEZA!$C$15),INCERTEZA!$D$15,IF(AND(I7=INCERTEZA!$B$16,J7=INCERTEZA!$C$16),INCERTEZA!$D$16,IF(AND(I7=INCERTEZA!$B$17,J7=INCERTEZA!$C$17),INCERTEZA!$D$17,"-"))))))))))))))) -> - | L7: =AEP!CX12 -> #N/A | M7: =AEP!CO12 -> #N/A | N7: =IF(AND(L7=monitoramento!$C$4,M7=monitoramento!$D$4),monitoramento!$E$4,IF(AND(L7=monitoramento!$C$5,M7=monitoramento!$D$5),monitoramento!$E$5,IF(AND(L7=monitoramento!$C$6,M7=monitoramento!$D$6),monitoramento!$E$6,IF(AND(L7=monitoramento!$C$7,M7=monitoramento!$D$7),monitoramento!$E$7,IF(AND(L7=monitoramento!$C$8,M7=monitoramento!$D$8),monitoramento!$E$8,IF(AND(L7=monitoramento!$C$9,M7=monitoramento!$D$9),monitoramento!$E$9,IF(AND(L7=monitoramento!$C$10,M7=monitoramento!$D$10),monitoramento!$E$10,IF(AND(L7=monitoramento!$C$11,M7=monitoramento!$D$11),monitoramento!$E$11,IF(AND(L7=monitoramento!$C$12,M7=monitoramento!$D$12),monitoramento!$E$12,IF(AND(L7=monitoramento!$C$13,M7=monitoramento!$D$13),monitoramento!$E$13,IF(AND(L7=monitoramento!$C$14,M7=monitoramento!$D$14),monitoramento!$E$14,IF(AND(L7=monitoramento!$C$15,M7=monitoramento!$D$15),monitoramento!$E$15,IF(AND(L7=monitoramento!$C$16,M7=monitoramento!$D$16),monitoramento!$E$16,IF(AND(L7=monitoramento!$C$17,M7=monitoramento!$D$17),monitoramento!$E$17,IF(AND(L7=monitoramento!$C$18,M7=monitoramento!$D$18),monitoramento!$E$18,IF(AND(L7=monitoramento!$C$19,M7=monitoramento!$D$19),monitoramento!$E$19)))))))))))))))) -> #N/A | T7: =SUM(T4:T6)*4 -> 0 | U7: =SUM(U4:U6) -> 0
H8: =AEP!BF13 | I8: =AEP!BI13 | J8: =AEP!BM13 -> 0 | K8: =IF(AND(I8=INCERTEZA!$B$3,J8=INCERTEZA!$C$3),INCERTEZA!$D$3,IF(AND(I8=INCERTEZA!$B$4,J8=INCERTEZA!$C$4),INCERTEZA!$D$4,IF(AND(I8=INCERTEZA!$B$5,J8=INCERTEZA!$C$5),INCERTEZA!$D$5,IF(AND(I8=INCERTEZA!$B$6,J8=INCERTEZA!$C$6),INCERTEZA!$D$6,IF(AND(I8=INCERTEZA!$B$7,J8=INCERTEZA!$C$7),INCERTEZA!$D$7,IF(AND(I8=INCERTEZA!$B$8,J8=INCERTEZA!$C$8),INCERTEZA!$D$8,IF(AND(I8=INCERTEZA!$B$9,J8=INCERTEZA!$C$9),INCERTEZA!$D$9,IF(AND(I8=INCERTEZA!$B$10,J8=INCERTEZA!$C$10),INCERTEZA!$D$10,IF(AND(I8=INCERTEZA!$B$11,J8=INCERTEZA!$C$11),INCERTEZA!$D$11,IF(AND(I8=INCERTEZA!$B$12,J8=INCERTEZA!$C$12),INCERTEZA!$D$12,IF(AND(I8=INCERTEZA!$B$13,J8=INCERTEZA!$C$13),INCERTEZA!$D$13,IF(AND(I8=INCERTEZA!$B$14,J8=INCERTEZA!$C$14),INCERTEZA!$D$14,IF(AND(I8=INCERTEZA!$B$15,J8=INCERTEZA!$C$15),INCERTEZA!$D$15,IF(AND(I8=INCERTEZA!$B$16,J8=INCERTEZA!$C$16),INCERTEZA!$D$16,IF(AND(I8=INCERTEZA!$B$17,J8=INCERTEZA!$C$17),INCERTEZA!$D$17,"-"))))))))))))))) -> - | L8: =AEP!CX13 -> #N/A | M8: =AEP!CO13 -> #N/A | N8: =IF(AND(L8=monitoramento!$C$4,M8=monitoramento!$D$4),monitoramento!$E$4,IF(AND(L8=monitoramento!$C$5,M8=monitoramento!$D$5),monitoramento!$E$5,IF(AND(L8=monitoramento!$C$6,M8=monitoramento!$D$6),monitoramento!$E$6,IF(AND(L8=monitoramento!$C$7,M8=monitoramento!$D$7),monitoramento!$E$7,IF(AND(L8=monitoramento!$C$8,M8=monitoramento!$D$8),monitoramento!$E$8,IF(AND(L8=monitoramento!$C$9,M8=monitoramento!$D$9),monitoramento!$E$9,IF(AND(L8=monitoramento!$C$10,M8=monitoramento!$D$10),monitoramento!$E$10,IF(AND(L8=monitoramento!$C$11,M8=monitoramento!$D$11),monitoramento!$E$11,IF(AND(L8=monitoramento!$C$12,M8=monitoramento!$D$12),monitoramento!$E$12,IF(AND(L8=monitoramento!$C$13,M8=monitoramento!$D$13),monitoramento!$E$13,IF(AND(L8=monitoramento!$C$14,M8=monitoramento!$D$14),monitoramento!$E$14,IF(AND(L8=monitoramento!$C$15,M8=monitoramento!$D$15),monitoramento!$E$15,IF(AND(L8=monitoramento!$C$16,M8=monitoramento!$D$16),monitoramento!$E$16,IF(AND(L8=monitoramento!$C$17,M8=monitoramento!$D$17),monitoramento!$E$17,IF(AND(L8=monitoramento!$C$18,M8=monitoramento!$D$18),monitoramento!$E$18,IF(AND(L8=monitoramento!$C$19,M8=monitoramento!$D$19),monitoramento!$E$19)))))))))))))))) -> #N/A
H9: =AEP!BF14 | I9: =AEP!BI14 | J9: =AEP!BM14 -> 0 | K9: =IF(AND(I9=INCERTEZA!$B$3,J9=INCERTEZA!$C$3),INCERTEZA!$D$3,IF(AND(I9=INCERTEZA!$B$4,J9=INCERTEZA!$C$4),INCERTEZA!$D$4,IF(AND(I9=INCERTEZA!$B$5,J9=INCERTEZA!$C$5),INCERTEZA!$D$5,IF(AND(I9=INCERTEZA!$B$6,J9=INCERTEZA!$C$6),INCERTEZA!$D$6,IF(AND(I9=INCERTEZA!$B$7,J9=INCERTEZA!$C$7),INCERTEZA!$D$7,IF(AND(I9=INCERTEZA!$B$8,J9=INCERTEZA!$C$8),INCERTEZA!$D$8,IF(AND(I9=INCERTEZA!$B$9,J9=INCERTEZA!$C$9),INCERTEZA!$D$9,IF(AND(I9=INCERTEZA!$B$10,J9=INCERTEZA!$C$10),INCERTEZA!$D$10,IF(AND(I9=INCERTEZA!$B$11,J9=INCERTEZA!$C$11),INCERTEZA!$D$11,IF(AND(I9=INCERTEZA!$B$12,J9=INCERTEZA!$C$12),INCERTEZA!$D$12,IF(AND(I9=INCERTEZA!$B$13,J9=INCERTEZA!$C$13),INCERTEZA!$D$13,IF(AND(I9=INCERTEZA!$B$14,J9=INCERTEZA!$C$14),INCERTEZA!$D$14,IF(AND(I9=INCERTEZA!$B$15,J9=INCERTEZA!$C$15),INCERTEZA!$D$15,IF(AND(I9=INCERTEZA!$B$16,J9=INCERTEZA!$C$16),INCERTEZA!$D$16,IF(AND(I9=INCERTEZA!$B$17,J9=INCERTEZA!$C$17),INCERTEZA!$D$17,"-"))))))))))))))) -> - | L9: =AEP!CX14 -> #N/A | M9: =AEP!CO14 -> #N/A | N9: =IF(AND(L9=monitoramento!$C$4,M9=monitoramento!$D$4),monitoramento!$E$4,IF(AND(L9=monitoramento!$C$5,M9=monitoramento!$D$5),monitoramento!$E$5,IF(AND(L9=monitoramento!$C$6,M9=monitoramento!$D$6),monitoramento!$E$6,IF(AND(L9=monitoramento!$C$7,M9=monitoramento!$D$7),monitoramento!$E$7,IF(AND(L9=monitoramento!$C$8,M9=monitoramento!$D$8),monitoramento!$E$8,IF(AND(L9=monitoramento!$C$9,M9=monitoramento!$D$9),monitoramento!$E$9,IF(AND(L9=monitoramento!$C$10,M9=monitoramento!$D$10),monitoramento!$E$10,IF(AND(L9=monitoramento!$C$11,M9=monitoramento!$D$11),monitoramento!$E$11,IF(AND(L9=monitoramento!$C$12,M9=monitoramento!$D$12),monitoramento!$E$12,IF(AND(L9=monitoramento!$C$13,M9=monitoramento!$D$13),monitoramento!$E$13,IF(AND(L9=monitoramento!$C$14,M9=monitoramento!$D$14),monitoramento!$E$14,IF(AND(L9=monitoramento!$C$15,M9=monitoramento!$D$15),monitoramento!$E$15,IF(AND(L9=monitoramento!$C$16,M9=monitoramento!$D$16),monitoramento!$E$16,IF(AND(L9=monitoramento!$C$17,M9=monitoramento!$D$17),monitoramento!$E$17,IF(AND(L9=monitoramento!$C$18,M9=monitoramento!$D$18),monitoramento!$E$18,IF(AND(L9=monitoramento!$C$19,M9=monitoramento!$D$19),monitoramento!$E$19)))))))))))))))) -> #N/A
H10: =AEP!BF15 | I10: =AEP!BI15 | J10: =AEP!BM15 -> 0 | K10: =IF(AND(I10=INCERTEZA!$B$3,J10=INCERTEZA!$C$3),INCERTEZA!$D$3,IF(AND(I10=INCERTEZA!$B$4,J10=INCERTEZA!$C$4),INCERTEZA!$D$4,IF(AND(I10=INCERTEZA!$B$5,J10=INCERTEZA!$C$5),INCERTEZA!$D$5,IF(AND(I10=INCERTEZA!$B$6,J10=INCERTEZA!$C$6),INCERTEZA!$D$6,IF(AND(I10=INCERTEZA!$B$7,J10=INCERTEZA!$C$7),INCERTEZA!$D$7,IF(AND(I10=INCERTEZA!$B$8,J10=INCERTEZA!$C$8),INCERTEZA!$D$8,IF(AND(I10=INCERTEZA!$B$9,J10=INCERTEZA!$C$9),INCERTEZA!$D$9,IF(AND(I10=INCERTEZA!$B$10,J10=INCERTEZA!$C$10),INCERTEZA!$D$10,IF(AND(I10=INCERTEZA!$B$11,J10=INCERTEZA!$C$11),INCERTEZA!$D$11,IF(AND(I10=INCERTEZA!$B$12,J10=INCERTEZA!$C$12),INCERTEZA!$D$12,IF(AND(I10=INCERTEZA!$B$13,J10=INCERTEZA!$C$13),INCERTEZA!$D$13,IF(AND(I10=INCERTEZA!$B$14,J10=INCERTEZA!$C$14),INCERTEZA!$D$14,IF(AND(I10=INCERTEZA!$B$15,J10=INCERTEZA!$C$15),INCERTEZA!$D$15,IF(AND(I10=INCERTEZA!$B$16,J10=INCERTEZA!$C$16),INCERTEZA!$D$16,IF(AND(I10=INCERTEZA!$B$17,J10=INCERTEZA!$C$17),INCERTEZA!$D$17,"-"))))))))))))))) -> - | L10: =AEP!CX15 -> #N/A | M10: =AEP!CO15 -> #N/A | N10: =IF(AND(L10=monitoramento!$C$4,M10=monitoramento!$D$4),monitoramento!$E$4,IF(AND(L10=monitoramento!$C$5,M10=monitoramento!$D$5),monitoramento!$E$5,IF(AND(L10=monitoramento!$C$6,M10=monitoramento!$D$6),monitoramento!$E$6,IF(AND(L10=monitoramento!$C$7,M10=monitoramento!$D$7),monitoramento!$E$7,IF(AND(L10=monitoramento!$C$8,M10=monitoramento!$D$8),monitoramento!$E$8,IF(AND(L10=monitoramento!$C$9,M10=monitoramento!$D$9),monitoramento!$E$9,IF(AND(L10=monitoramento!$C$10,M10=monitoramento!$D$10),monitoramento!$E$10,IF(AND(L10=monitoramento!$C$11,M10=monitoramento!$D$11),monitoramento!$E$11,IF(AND(L10=monitoramento!$C$12,M10=monitoramento!$D$12),monitoramento!$E$12,IF(AND(L10=monitoramento!$C$13,M10=monitoramento!$D$13),monitoramento!$E$13,IF(AND(L10=monitoramento!$C$14,M10=monitoramento!$D$14),monitoramento!$E$14,IF(AND(L10=monitoramento!$C$15,M10=monitoramento!$D$15),monitoramento!$E$15,IF(AND(L10=monitoramento!$C$16,M10=monitoramento!$D$16),monitoramento!$E$16,IF(AND(L10=monitoramento!$C$17,M10=monitoramento!$D$17),monitoramento!$E$17,IF(AND(L10=monitoramento!$C$18,M10=monitoramento!$D$18),monitoramento!$E$18,IF(AND(L10=monitoramento!$C$19,M10=monitoramento!$D$19),monitoramento!$E$19)))))))))))))))) -> #N/A
H11: =AEP!BF16 | I11: =AEP!BI16 | J11: =AEP!BM16 -> 0 | K11: =IF(AND(I11=INCERTEZA!$B$3,J11=INCERTEZA!$C$3),INCERTEZA!$D$3,IF(AND(I11=INCERTEZA!$B$4,J11=INCERTEZA!$C$4),INCERTEZA!$D$4,IF(AND(I11=INCERTEZA!$B$5,J11=INCERTEZA!$C$5),INCERTEZA!$D$5,IF(AND(I11=INCERTEZA!$B$6,J11=INCERTEZA!$C$6),INCERTEZA!$D$6,IF(AND(I11=INCERTEZA!$B$7,J11=INCERTEZA!$C$7),INCERTEZA!$D$7,IF(AND(I11=INCERTEZA!$B$8,J11=INCERTEZA!$C$8),INCERTEZA!$D$8,IF(AND(I11=INCERTEZA!$B$9,J11=INCERTEZA!$C$9),INCERTEZA!$D$9,IF(AND(I11=INCERTEZA!$B$10,J11=INCERTEZA!$C$10),INCERTEZA!$D$10,IF(AND(I11=INCERTEZA!$B$11,J11=INCERTEZA!$C$11),INCERTEZA!$D$11,IF(AND(I11=INCERTEZA!$B$12,J11=INCERTEZA!$C$12),INCERTEZA!$D$12,IF(AND(I11=INCERTEZA!$B$13,J11=INCERTEZA!$C$13),INCERTEZA!$D$13,IF(AND(I11=INCERTEZA!$B$14,J11=INCERTEZA!$C$14),INCERTEZA!$D$14,IF(AND(I11=INCERTEZA!$B$15,J11=INCERTEZA!$C$15),INCERTEZA!$D$15,IF(AND(I11=INCERTEZA!$B$16,J11=INCERTEZA!$C$16),INCERTEZA!$D$16,IF(AND(I11=INCERTEZA!$B$17,J11=INCERTEZA!$C$17),INCERTEZA!$D$17,"-"))))))))))))))) -> - | L11: =AEP!CX16 -> #N/A | M11: =AEP!CO16 -> #N/A | N11: =IF(AND(L11=monitoramento!$C$4,M11=monitoramento!$D$4),monitoramento!$E$4,IF(AND(L11=monitoramento!$C$5,M11=monitoramento!$D$5),monitoramento!$E$5,IF(AND(L11=monitoramento!$C$6,M11=monitoramento!$D$6),monitoramento!$E$6,IF(AND(L11=monitoramento!$C$7,M11=monitoramento!$D$7),monitoramento!$E$7,IF(AND(L11=monitoramento!$C$8,M11=monitoramento!$D$8),monitoramento!$E$8,IF(AND(L11=monitoramento!$C$9,M11=monitoramento!$D$9),monitoramento!$E$9,IF(AND(L11=monitoramento!$C$10,M11=monitoramento!$D$10),monitoramento!$E$10,IF(AND(L11=monitoramento!$C$11,M11=monitoramento!$D$11),monitoramento!$E$11,IF(AND(L11=monitoramento!$C$12,M11=monitoramento!$D$12),monitoramento!$E$12,IF(AND(L11=monitoramento!$C$13,M11=monitoramento!$D$13),monitoramento!$E$13,IF(AND(L11=monitoramento!$C$14,M11=monitoramento!$D$14),monitoramento!$E$14,IF(AND(L11=monitoramento!$C$15,M11=monitoramento!$D$15),monitoramento!$E$15,IF(AND(L11=monitoramento!$C$16,M11=monitoramento!$D$16),monitoramento!$E$16,IF(AND(L11=monitoramento!$C$17,M11=monitoramento!$D$17),monitoramento!$E$17,IF(AND(L11=monitoramento!$C$18,M11=monitoramento!$D$18),monitoramento!$E$18,IF(AND(L11=monitoramento!$C$19,M11=monitoramento!$D$19),monitoramento!$E$19)))))))))))))))) -> #N/A
H12: =AEP!BF17 | I12: =AEP!BI17 | J12: =AEP!BM17 -> 0 | K12: =IF(AND(I12=INCERTEZA!$B$3,J12=INCERTEZA!$C$3),INCERTEZA!$D$3,IF(AND(I12=INCERTEZA!$B$4,J12=INCERTEZA!$C$4),INCERTEZA!$D$4,IF(AND(I12=INCERTEZA!$B$5,J12=INCERTEZA!$C$5),INCERTEZA!$D$5,IF(AND(I12=INCERTEZA!$B$6,J12=INCERTEZA!$C$6),INCERTEZA!$D$6,IF(AND(I12=INCERTEZA!$B$7,J12=INCERTEZA!$C$7),INCERTEZA!$D$7,IF(AND(I12=INCERTEZA!$B$8,J12=INCERTEZA!$C$8),INCERTEZA!$D$8,IF(AND(I12=INCERTEZA!$B$9,J12=INCERTEZA!$C$9),INCERTEZA!$D$9,IF(AND(I12=INCERTEZA!$B$10,J12=INCERTEZA!$C$10),INCERTEZA!$D$10,IF(AND(I12=INCERTEZA!$B$11,J12=INCERTEZA!$C$11),INCERTEZA!$D$11,IF(AND(I12=INCERTEZA!$B$12,J12=INCERTEZA!$C$12),INCERTEZA!$D$12,IF(AND(I12=INCERTEZA!$B$13,J12=INCERTEZA!$C$13),INCERTEZA!$D$13,IF(AND(I12=INCERTEZA!$B$14,J12=INCERTEZA!$C$14),INCERTEZA!$D$14,IF(AND(I12=INCERTEZA!$B$15,J12=INCERTEZA!$C$15),INCERTEZA!$D$15,IF(AND(I12=INCERTEZA!$B$16,J12=INCERTEZA!$C$16),INCERTEZA!$D$16,IF(AND(I12=INCERTEZA!$B$17,J12=INCERTEZA!$C$17),INCERTEZA!$D$17,"-"))))))))))))))) -> - | L12: =AEP!CX17 -> #N/A | M12: =AEP!CO17 -> #N/A | N12: =IF(AND(L12=monitoramento!$C$4,M12=monitoramento!$D$4),monitoramento!$E$4,IF(AND(L12=monitoramento!$C$5,M12=monitoramento!$D$5),monitoramento!$E$5,IF(AND(L12=monitoramento!$C$6,M12=monitoramento!$D$6),monitoramento!$E$6,IF(AND(L12=monitoramento!$C$7,M12=monitoramento!$D$7),monitoramento!$E$7,IF(AND(L12=monitoramento!$C$8,M12=monitoramento!$D$8),monitoramento!$E$8,IF(AND(L12=monitoramento!$C$9,M12=monitoramento!$D$9),monitoramento!$E$9,IF(AND(L12=monitoramento!$C$10,M12=monitoramento!$D$10),monitoramento!$E$10,IF(AND(L12=monitoramento!$C$11,M12=monitoramento!$D$11),monitoramento!$E$11,IF(AND(L12=monitoramento!$C$12,M12=monitoramento!$D$12),monitoramento!$E$12,IF(AND(L12=monitoramento!$C$13,M12=monitoramento!$D$13),monitoramento!$E$13,IF(AND(L12=monitoramento!$C$14,M12=monitoramento!$D$14),monitoramento!$E$14,IF(AND(L12=monitoramento!$C$15,M12=monitoramento!$D$15),monitoramento!$E$15,IF(AND(L12=monitoramento!$C$16,M12=monitoramento!$D$16),monitoramento!$E$16,IF(AND(L12=monitoramento!$C$17,M12=monitoramento!$D$17),monitoramento!$E$17,IF(AND(L12=monitoramento!$C$18,M12=monitoramento!$D$18),monitoramento!$E$18,IF(AND(L12=monitoramento!$C$19,M12=monitoramento!$D$19),monitoramento!$E$19)))))))))))))))) -> #N/A
H13: =AEP!BF18 | I13: =AEP!BI18 | J13: =AEP!BM18 -> 0 | K13: =IF(AND(I13=INCERTEZA!$B$3,J13=INCERTEZA!$C$3),INCERTEZA!$D$3,IF(AND(I13=INCERTEZA!$B$4,J13=INCERTEZA!$C$4),INCERTEZA!$D$4,IF(AND(I13=INCERTEZA!$B$5,J13=INCERTEZA!$C$5),INCERTEZA!$D$5,IF(AND(I13=INCERTEZA!$B$6,J13=INCERTEZA!$C$6),INCERTEZA!$D$6,IF(AND(I13=INCERTEZA!$B$7,J13=INCERTEZA!$C$7),INCERTEZA!$D$7,IF(AND(I13=INCERTEZA!$B$8,J13=INCERTEZA!$C$8),INCERTEZA!$D$8,IF(AND(I13=INCERTEZA!$B$9,J13=INCERTEZA!$C$9),INCERTEZA!$D$9,IF(AND(I13=INCERTEZA!$B$10,J13=INCERTEZA!$C$10),INCERTEZA!$D$10,IF(AND(I13=INCERTEZA!$B$11,J13=INCERTEZA!$C$11),INCERTEZA!$D$11,IF(AND(I13=INCERTEZA!$B$12,J13=INCERTEZA!$C$12),INCERTEZA!$D$12,IF(AND(I13=INCERTEZA!$B$13,J13=INCERTEZA!$C$13),INCERTEZA!$D$13,IF(AND(I13=INCERTEZA!$B$14,J13=INCERTEZA!$C$14),INCERTEZA!$D$14,IF(AND(I13=INCERTEZA!$B$15,J13=INCERTEZA!$C$15),INCERTEZA!$D$15,IF(AND(I13=INCERTEZA!$B$16,J13=INCERTEZA!$C$16),INCERTEZA!$D$16,IF(AND(I13=INCERTEZA!$B$17,J13=INCERTEZA!$C$17),INCERTEZA!$D$17,"-"))))))))))))))) -> - | L13: =AEP!CX18 -> #N/A | M13: =AEP!CO18 -> #N/A | N13: =IF(AND(L13=monitoramento!$C$4,M13=monitoramento!$D$4),monitoramento!$E$4,IF(AND(L13=monitoramento!$C$5,M13=monitoramento!$D$5),monitoramento!$E$5,IF(AND(L13=monitoramento!$C$6,M13=monitoramento!$D$6),monitoramento!$E$6,IF(AND(L13=monitoramento!$C$7,M13=monitoramento!$D$7),monitoramento!$E$7,IF(AND(L13=monitoramento!$C$8,M13=monitoramento!$D$8),monitoramento!$E$8,IF(AND(L13=monitoramento!$C$9,M13=monitoramento!$D$9),monitoramento!$E$9,IF(AND(L13=monitoramento!$C$10,M13=monitoramento!$D$10),monitoramento!$E$10,IF(AND(L13=monitoramento!$C$11,M13=monitoramento!$D$11),monitoramento!$E$11,IF(AND(L13=monitoramento!$C$12,M13=monitoramento!$D$12),monitoramento!$E$12,IF(AND(L13=monitoramento!$C$13,M13=monitoramento!$D$13),monitoramento!$E$13,IF(AND(L13=monitoramento!$C$14,M13=monitoramento!$D$14),monitoramento!$E$14,IF(AND(L13=monitoramento!$C$15,M13=monitoramento!$D$15),monitoramento!$E$15,IF(AND(L13=monitoramento!$C$16,M13=monitoramento!$D$16),monitoramento!$E$16,IF(AND(L13=monitoramento!$C$17,M13=monitoramento!$D$17),monitoramento!$E$17,IF(AND(L13=monitoramento!$C$18,M13=monitoramento!$D$18),monitoramento!$E$18,IF(AND(L13=monitoramento!$C$19,M13=monitoramento!$D$19),monitoramento!$E$19)))))))))))))))) -> #N/A
H14: =AEP!BF19 | I14: =AEP!BI19 | J14: =AEP!BM19 -> 0 | K14: =IF(AND(I14=INCERTEZA!$B$3,J14=INCERTEZA!$C$3),INCERTEZA!$D$3,IF(AND(I14=INCERTEZA!$B$4,J14=INCERTEZA!$C$4),INCERTEZA!$D$4,IF(AND(I14=INCERTEZA!$B$5,J14=INCERTEZA!$C$5),INCERTEZA!$D$5,IF(AND(I14=INCERTEZA!$B$6,J14=INCERTEZA!$C$6),INCERTEZA!$D$6,IF(AND(I14=INCERTEZA!$B$7,J14=INCERTEZA!$C$7),INCERTEZA!$D$7,IF(AND(I14=INCERTEZA!$B$8,J14=INCERTEZA!$C$8),INCERTEZA!$D$8,IF(AND(I14=INCERTEZA!$B$9,J14=INCERTEZA!$C$9),INCERTEZA!$D$9,IF(AND(I14=INCERTEZA!$B$10,J14=INCERTEZA!$C$10),INCERTEZA!$D$10,IF(AND(I14=INCERTEZA!$B$11,J14=INCERTEZA!$C$11),INCERTEZA!$D$11,IF(AND(I14=INCERTEZA!$B$12,J14=INCERTEZA!$C$12),INCERTEZA!$D$12,IF(AND(I14=INCERTEZA!$B$13,J14=INCERTEZA!$C$13),INCERTEZA!$D$13,IF(AND(I14=INCERTEZA!$B$14,J14=INCERTEZA!$C$14),INCERTEZA!$D$14,IF(AND(I14=INCERTEZA!$B$15,J14=INCERTEZA!$C$15),INCERTEZA!$D$15,IF(AND(I14=INCERTEZA!$B$16,J14=INCERTEZA!$C$16),INCERTEZA!$D$16,IF(AND(I14=INCERTEZA!$B$17,J14=INCERTEZA!$C$17),INCERTEZA!$D$17,"-"))))))))))))))) -> - | L14: =AEP!CX19 -> #N/A | M14: =AEP!CO19 -> #N/A | N14: =IF(AND(L14=monitoramento!$C$4,M14=monitoramento!$D$4),monitoramento!$E$4,IF(AND(L14=monitoramento!$C$5,M14=monitoramento!$D$5),monitoramento!$E$5,IF(AND(L14=monitoramento!$C$6,M14=monitoramento!$D$6),monitoramento!$E$6,IF(AND(L14=monitoramento!$C$7,M14=monitoramento!$D$7),monitoramento!$E$7,IF(AND(L14=monitoramento!$C$8,M14=monitoramento!$D$8),monitoramento!$E$8,IF(AND(L14=monitoramento!$C$9,M14=monitoramento!$D$9),monitoramento!$E$9,IF(AND(L14=monitoramento!$C$10,M14=monitoramento!$D$10),monitoramento!$E$10,IF(AND(L14=monitoramento!$C$11,M14=monitoramento!$D$11),monitoramento!$E$11,IF(AND(L14=monitoramento!$C$12,M14=monitoramento!$D$12),monitoramento!$E$12,IF(AND(L14=monitoramento!$C$13,M14=monitoramento!$D$13),monitoramento!$E$13,IF(AND(L14=monitoramento!$C$14,M14=monitoramento!$D$14),monitoramento!$E$14,IF(AND(L14=monitoramento!$C$15,M14=monitoramento!$D$15),monitoramento!$E$15,IF(AND(L14=monitoramento!$C$16,M14=monitoramento!$D$16),monitoramento!$E$16,IF(AND(L14=monitoramento!$C$17,M14=monitoramento!$D$17),monitoramento!$E$17,IF(AND(L14=monitoramento!$C$18,M14=monitoramento!$D$18),monitoramento!$E$18,IF(AND(L14=monitoramento!$C$19,M14=monitoramento!$D$19),monitoramento!$E$19)))))))))))))))) -> #N/A
H15: =AEP!BF20 | I15: =AEP!BI20 | J15: =AEP!BM20 -> 0 | K15: =IF(AND(I15=INCERTEZA!$B$3,J15=INCERTEZA!$C$3),INCERTEZA!$D$3,IF(AND(I15=INCERTEZA!$B$4,J15=INCERTEZA!$C$4),INCERTEZA!$D$4,IF(AND(I15=INCERTEZA!$B$5,J15=INCERTEZA!$C$5),INCERTEZA!$D$5,IF(AND(I15=INCERTEZA!$B$6,J15=INCERTEZA!$C$6),INCERTEZA!$D$6,IF(AND(I15=INCERTEZA!$B$7,J15=INCERTEZA!$C$7),INCERTEZA!$D$7,IF(AND(I15=INCERTEZA!$B$8,J15=INCERTEZA!$C$8),INCERTEZA!$D$8,IF(AND(I15=INCERTEZA!$B$9,J15=INCERTEZA!$C$9),INCERTEZA!$D$9,IF(AND(I15=INCERTEZA!$B$10,J15=INCERTEZA!$C$10),INCERTEZA!$D$10,IF(AND(I15=INCERTEZA!$B$11,J15=INCERTEZA!$C$11),INCERTEZA!$D$11,IF(AND(I15=INCERTEZA!$B$12,J15=INCERTEZA!$C$12),INCERTEZA!$D$12,IF(AND(I15=INCERTEZA!$B$13,J15=INCERTEZA!$C$13),INCERTEZA!$D$13,IF(AND(I15=INCERTEZA!$B$14,J15=INCERTEZA!$C$14),INCERTEZA!$D$14,IF(AND(I15=INCERTEZA!$B$15,J15=INCERTEZA!$C$15),INCERTEZA!$D$15,IF(AND(I15=INCERTEZA!$B$16,J15=INCERTEZA!$C$16),INCERTEZA!$D$16,IF(AND(I15=INCERTEZA!$B$17,J15=INCERTEZA!$C$17),INCERTEZA!$D$17,"-"))))))))))))))) -> - | L15: =AEP!CX20 -> #N/A | M15: =AEP!CO20 -> #N/A | N15: =IF(AND(L15=monitoramento!$C$4,M15=monitoramento!$D$4),monitoramento!$E$4,IF(AND(L15=monitoramento!$C$5,M15=monitoramento!$D$5),monitoramento!$E$5,IF(AND(L15=monitoramento!$C$6,M15=monitoramento!$D$6),monitoramento!$E$6,IF(AND(L15=monitoramento!$C$7,M15=monitoramento!$D$7),monitoramento!$E$7,IF(AND(L15=monitoramento!$C$8,M15=monitoramento!$D$8),monitoramento!$E$8,IF(AND(L15=monitoramento!$C$9,M15=monitoramento!$D$9),monitoramento!$E$9,IF(AND(L15=monitoramento!$C$10,M15=monitoramento!$D$10),monitoramento!$E$10,IF(AND(L15=monitoramento!$C$11,M15=monitoramento!$D$11),monitoramento!$E$11,IF(AND(L15=monitoramento!$C$12,M15=monitoramento!$D$12),monitoramento!$E$12,IF(AND(L15=monitoramento!$C$13,M15=monitoramento!$D$13),monitoramento!$E$13,IF(AND(L15=monitoramento!$C$14,M15=monitoramento!$D$14),monitoramento!$E$14,IF(AND(L15=monitoramento!$C$15,M15=monitoramento!$D$15),monitoramento!$E$15,IF(AND(L15=monitoramento!$C$16,M15=monitoramento!$D$16),monitoramento!$E$16,IF(AND(L15=monitoramento!$C$17,M15=monitoramento!$D$17),monitoramento!$E$17,IF(AND(L15=monitoramento!$C$18,M15=monitoramento!$D$18),monitoramento!$E$18,IF(AND(L15=monitoramento!$C$19,M15=monitoramento!$D$19),monitoramento!$E$19)))))))))))))))) -> #N/A
H16: =AEP!BF21 | I16: =AEP!BI21 | J16: =AEP!BM21 -> 0 | K16: =IF(AND(I16=INCERTEZA!$B$3,J16=INCERTEZA!$C$3),INCERTEZA!$D$3,IF(AND(I16=INCERTEZA!$B$4,J16=INCERTEZA!$C$4),INCERTEZA!$D$4,IF(AND(I16=INCERTEZA!$B$5,J16=INCERTEZA!$C$5),INCERTEZA!$D$5,IF(AND(I16=INCERTEZA!$B$6,J16=INCERTEZA!$C$6),INCERTEZA!$D$6,IF(AND(I16=INCERTEZA!$B$7,J16=INCERTEZA!$C$7),INCERTEZA!$D$7,IF(AND(I16=INCERTEZA!$B$8,J16=INCERTEZA!$C$8),INCERTEZA!$D$8,IF(AND(I16=INCERTEZA!$B$9,J16=INCERTEZA!$C$9),INCERTEZA!$D$9,IF(AND(I16=INCERTEZA!$B$10,J16=INCERTEZA!$C$10),INCERTEZA!$D$10,IF(AND(I16=INCERTEZA!$B$11,J16=INCERTEZA!$C$11),INCERTEZA!$D$11,IF(AND(I16=INCERTEZA!$B$12,J16=INCERTEZA!$C$12),INCERTEZA!$D$12,IF(AND(I16=INCERTEZA!$B$13,J16=INCERTEZA!$C$13),INCERTEZA!$D$13,IF(AND(I16=INCERTEZA!$B$14,J16=INCERTEZA!$C$14),INCERTEZA!$D$14,IF(AND(I16=INCERTEZA!$B$15,J16=INCERTEZA!$C$15),INCERTEZA!$D$15,IF(AND(I16=INCERTEZA!$B$16,J16=INCERTEZA!$C$16),INCERTEZA!$D$16,IF(AND(I16=INCERTEZA!$B$17,J16=INCERTEZA!$C$17),INCERTEZA!$D$17,"-"))))))))))))))) -> - | L16: =AEP!CX21 -> #N/A | M16: =AEP!CO21 -> #N/A | N16: =IF(AND(L16=monitoramento!$C$4,M16=monitoramento!$D$4),monitoramento!$E$4,IF(AND(L16=monitoramento!$C$5,M16=monitoramento!$D$5),monitoramento!$E$5,IF(AND(L16=monitoramento!$C$6,M16=monitoramento!$D$6),monitoramento!$E$6,IF(AND(L16=monitoramento!$C$7,M16=monitoramento!$D$7),monitoramento!$E$7,IF(AND(L16=monitoramento!$C$8,M16=monitoramento!$D$8),monitoramento!$E$8,IF(AND(L16=monitoramento!$C$9,M16=monitoramento!$D$9),monitoramento!$E$9,IF(AND(L16=monitoramento!$C$10,M16=monitoramento!$D$10),monitoramento!$E$10,IF(AND(L16=monitoramento!$C$11,M16=monitoramento!$D$11),monitoramento!$E$11,IF(AND(L16=monitoramento!$C$12,M16=monitoramento!$D$12),monitoramento!$E$12,IF(AND(L16=monitoramento!$C$13,M16=monitoramento!$D$13),monitoramento!$E$13,IF(AND(L16=monitoramento!$C$14,M16=monitoramento!$D$14),monitoramento!$E$14,IF(AND(L16=monitoramento!$C$15,M16=monitoramento!$D$15),monitoramento!$E$15,IF(AND(L16=monitoramento!$C$16,M16=monitoramento!$D$16),monitoramento!$E$16,IF(AND(L16=monitoramento!$C$17,M16=monitoramento!$D$17),monitoramento!$E$17,IF(AND(L16=monitoramento!$C$18,M16=monitoramento!$D$18),monitoramento!$E$18,IF(AND(L16=monitoramento!$C$19,M16=monitoramento!$D$19),monitoramento!$E$19)))))))))))))))) -> #N/A
H17: =AEP!BF22 | I17: =AEP!BI22 | J17: =AEP!BM22 -> 0 | K17: =IF(AND(I17=INCERTEZA!$B$3,J17=INCERTEZA!$C$3),INCERTEZA!$D$3,IF(AND(I17=INCERTEZA!$B$4,J17=INCERTEZA!$C$4),INCERTEZA!$D$4,IF(AND(I17=INCERTEZA!$B$5,J17=INCERTEZA!$C$5),INCERTEZA!$D$5,IF(AND(I17=INCERTEZA!$B$6,J17=INCERTEZA!$C$6),INCERTEZA!$D$6,IF(AND(I17=INCERTEZA!$B$7,J17=INCERTEZA!$C$7),INCERTEZA!$D$7,IF(AND(I17=INCERTEZA!$B$8,J17=INCERTEZA!$C$8),INCERTEZA!$D$8,IF(AND(I17=INCERTEZA!$B$9,J17=INCERTEZA!$C$9),INCERTEZA!$D$9,IF(AND(I17=INCERTEZA!$B$10,J17=INCERTEZA!$C$10),INCERTEZA!$D$10,IF(AND(I17=INCERTEZA!$B$11,J17=INCERTEZA!$C$11),INCERTEZA!$D$11,IF(AND(I17=INCERTEZA!$B$12,J17=INCERTEZA!$C$12),INCERTEZA!$D$12,IF(AND(I17=INCERTEZA!$B$13,J17=INCERTEZA!$C$13),INCERTEZA!$D$13,IF(AND(I17=INCERTEZA!$B$14,J17=INCERTEZA!$C$14),INCERTEZA!$D$14,IF(AND(I17=INCERTEZA!$B$15,J17=INCERTEZA!$C$15),INCERTEZA!$D$15,IF(AND(I17=INCERTEZA!$B$16,J17=INCERTEZA!$C$16),INCERTEZA!$D$16,IF(AND(I17=INCERTEZA!$B$17,J17=INCERTEZA!$C$17),INCERTEZA!$D$17,"-"))))))))))))))) -> - | L17: =AEP!CX22 -> #N/A | M17: =AEP!CO22 -> #N/A | N17: =IF(AND(L17=monitoramento!$C$4,M17=monitoramento!$D$4),monitoramento!$E$4,IF(AND(L17=monitoramento!$C$5,M17=monitoramento!$D$5),monitoramento!$E$5,IF(AND(L17=monitoramento!$C$6,M17=monitoramento!$D$6),monitoramento!$E$6,IF(AND(L17=monitoramento!$C$7,M17=monitoramento!$D$7),monitoramento!$E$7,IF(AND(L17=monitoramento!$C$8,M17=monitoramento!$D$8),monitoramento!$E$8,IF(AND(L17=monitoramento!$C$9,M17=monitoramento!$D$9),monitoramento!$E$9,IF(AND(L17=monitoramento!$C$10,M17=monitoramento!$D$10),monitoramento!$E$10,IF(AND(L17=monitoramento!$C$11,M17=monitoramento!$D$11),monitoramento!$E$11,IF(AND(L17=monitoramento!$C$12,M17=monitoramento!$D$12),monitoramento!$E$12,IF(AND(L17=monitoramento!$C$13,M17=monitoramento!$D$13),monitoramento!$E$13,IF(AND(L17=monitoramento!$C$14,M17=monitoramento!$D$14),monitoramento!$E$14,IF(AND(L17=monitoramento!$C$15,M17=monitoramento!$D$15),monitoramento!$E$15,IF(AND(L17=monitoramento!$C$16,M17=monitoramento!$D$16),monitoramento!$E$16,IF(AND(L17=monitoramento!$C$17,M17=monitoramento!$D$17),monitoramento!$E$17,IF(AND(L17=monitoramento!$C$18,M17=monitoramento!$D$18),monitoramento!$E$18,IF(AND(L17=monitoramento!$C$19,M17=monitoramento!$D$19),monitoramento!$E$19)))))))))))))))) -> #N/A
H18: =AEP!BF23 | I18: =AEP!BI23 | J18: =AEP!BM23 -> 0 | K18: =IF(AND(I18=INCERTEZA!$B$3,J18=INCERTEZA!$C$3),INCERTEZA!$D$3,IF(AND(I18=INCERTEZA!$B$4,J18=INCERTEZA!$C$4),INCERTEZA!$D$4,IF(AND(I18=INCERTEZA!$B$5,J18=INCERTEZA!$C$5),INCERTEZA!$D$5,IF(AND(I18=INCERTEZA!$B$6,J18=INCERTEZA!$C$6),INCERTEZA!$D$6,IF(AND(I18=INCERTEZA!$B$7,J18=INCERTEZA!$C$7),INCERTEZA!$D$7,IF(AND(I18=INCERTEZA!$B$8,J18=INCERTEZA!$C$8),INCERTEZA!$D$8,IF(AND(I18=INCERTEZA!$B$9,J18=INCERTEZA!$C$9),INCERTEZA!$D$9,IF(AND(I18=INCERTEZA!$B$10,J18=INCERTEZA!$C$10),INCERTEZA!$D$10,IF(AND(I18=INCERTEZA!$B$11,J18=INCERTEZA!$C$11),INCERTEZA!$D$11,IF(AND(I18=INCERTEZA!$B$12,J18=INCERTEZA!$C$12),INCERTEZA!$D$12,IF(AND(I18=INCERTEZA!$B$13,J18=INCERTEZA!$C$13),INCERTEZA!$D$13,IF(AND(I18=INCERTEZA!$B$14,J18=INCERTEZA!$C$14),INCERTEZA!$D$14,IF(AND(I18=INCERTEZA!$B$15,J18=INCERTEZA!$C$15),INCERTEZA!$D$15,IF(AND(I18=INCERTEZA!$B$16,J18=INCERTEZA!$C$16),INCERTEZA!$D$16,IF(AND(I18=INCERTEZA!$B$17,J18=INCERTEZA!$C$17),INCERTEZA!$D$17,"-"))))))))))))))) -> - | L18: =AEP!CX23 -> #N/A | M18: =AEP!CO23 -> #N/A | N18: =IF(AND(L18=monitoramento!$C$4,M18=monitoramento!$D$4),monitoramento!$E$4,IF(AND(L18=monitoramento!$C$5,M18=monitoramento!$D$5),monitoramento!$E$5,IF(AND(L18=monitoramento!$C$6,M18=monitoramento!$D$6),monitoramento!$E$6,IF(AND(L18=monitoramento!$C$7,M18=monitoramento!$D$7),monitoramento!$E$7,IF(AND(L18=monitoramento!$C$8,M18=monitoramento!$D$8),monitoramento!$E$8,IF(AND(L18=monitoramento!$C$9,M18=monitoramento!$D$9),monitoramento!$E$9,IF(AND(L18=monitoramento!$C$10,M18=monitoramento!$D$10),monitoramento!$E$10,IF(AND(L18=monitoramento!$C$11,M18=monitoramento!$D$11),monitoramento!$E$11,IF(AND(L18=monitoramento!$C$12,M18=monitoramento!$D$12),monitoramento!$E$12,IF(AND(L18=monitoramento!$C$13,M18=monitoramento!$D$13),monitoramento!$E$13,IF(AND(L18=monitoramento!$C$14,M18=monitoramento!$D$14),monitoramento!$E$14,IF(AND(L18=monitoramento!$C$15,M18=monitoramento!$D$15),monitoramento!$E$15,IF(AND(L18=monitoramento!$C$16,M18=monitoramento!$D$16),monitoramento!$E$16,IF(AND(L18=monitoramento!$C$17,M18=monitoramento!$D$17),monitoramento!$E$17,IF(AND(L18=monitoramento!$C$18,M18=monitoramento!$D$18),monitoramento!$E$18,IF(AND(L18=monitoramento!$C$19,M18=monitoramento!$D$19),monitoramento!$E$19)))))))))))))))) -> #N/A
H19: =AEP!BF24 | I19: =AEP!BI24 | J19: =AEP!BM24 -> 0 | K19: =IF(AND(I19=INCERTEZA!$B$3,J19=INCERTEZA!$C$3),INCERTEZA!$D$3,IF(AND(I19=INCERTEZA!$B$4,J19=INCERTEZA!$C$4),INCERTEZA!$D$4,IF(AND(I19=INCERTEZA!$B$5,J19=INCERTEZA!$C$5),INCERTEZA!$D$5,IF(AND(I19=INCERTEZA!$B$6,J19=INCERTEZA!$C$6),INCERTEZA!$D$6,IF(AND(I19=INCERTEZA!$B$7,J19=INCERTEZA!$C$7),INCERTEZA!$D$7,IF(AND(I19=INCERTEZA!$B$8,J19=INCERTEZA!$C$8),INCERTEZA!$D$8,IF(AND(I19=INCERTEZA!$B$9,J19=INCERTEZA!$C$9),INCERTEZA!$D$9,IF(AND(I19=INCERTEZA!$B$10,J19=INCERTEZA!$C$10),INCERTEZA!$D$10,IF(AND(I19=INCERTEZA!$B$11,J19=INCERTEZA!$C$11),INCERTEZA!$D$11,IF(AND(I19=INCERTEZA!$B$12,J19=INCERTEZA!$C$12),INCERTEZA!$D$12,IF(AND(I19=INCERTEZA!$B$13,J19=INCERTEZA!$C$13),INCERTEZA!$D$13,IF(AND(I19=INCERTEZA!$B$14,J19=INCERTEZA!$C$14),INCERTEZA!$D$14,IF(AND(I19=INCERTEZA!$B$15,J19=INCERTEZA!$C$15),INCERTEZA!$D$15,IF(AND(I19=INCERTEZA!$B$16,J19=INCERTEZA!$C$16),INCERTEZA!$D$16,IF(AND(I19=INCERTEZA!$B$17,J19=INCERTEZA!$C$17),INCERTEZA!$D$17,"-"))))))))))))))) -> - | L19: =AEP!CX24 -> #N/A | M19: =AEP!CO24 -> #N/A | N19: =IF(AND(L19=monitoramento!$C$4,M19=monitoramento!$D$4),monitoramento!$E$4,IF(AND(L19=monitoramento!$C$5,M19=monitoramento!$D$5),monitoramento!$E$5,IF(AND(L19=monitoramento!$C$6,M19=monitoramento!$D$6),monitoramento!$E$6,IF(AND(L19=monitoramento!$C$7,M19=monitoramento!$D$7),monitoramento!$E$7,IF(AND(L19=monitoramento!$C$8,M19=monitoramento!$D$8),monitoramento!$E$8,IF(AND(L19=monitoramento!$C$9,M19=monitoramento!$D$9),monitoramento!$E$9,IF(AND(L19=monitoramento!$C$10,M19=monitoramento!$D$10),monitoramento!$E$10,IF(AND(L19=monitoramento!$C$11,M19=monitoramento!$D$11),monitoramento!$E$11,IF(AND(L19=monitoramento!$C$12,M19=monitoramento!$D$12),monitoramento!$E$12,IF(AND(L19=monitoramento!$C$13,M19=monitoramento!$D$13),monitoramento!$E$13,IF(AND(L19=monitoramento!$C$14,M19=monitoramento!$D$14),monitoramento!$E$14,IF(AND(L19=monitoramento!$C$15,M19=monitoramento!$D$15),monitoramento!$E$15,IF(AND(L19=monitoramento!$C$16,M19=monitoramento!$D$16),monitoramento!$E$16,IF(AND(L19=monitoramento!$C$17,M19=monitoramento!$D$17),monitoramento!$E$17,IF(AND(L19=monitoramento!$C$18,M19=monitoramento!$D$18),monitoramento!$E$18,IF(AND(L19=monitoramento!$C$19,M19=monitoramento!$D$19),monitoramento!$E$19)))))))))))))))) -> #N/A
... H183: =AEP!BF188 -> 0 | I183: =AEP!BI188 -> 0 | J183: =AEP!BM188 -> 0 | K183: =IF(AND(I183=INCERTEZA!$B$3,J183=INCERTEZA!$C$3),INCERTEZA!$D$3,IF(AND(I183=INCERTEZA!$B$4,J183=INCERTEZA!$C$4),INCERTEZA!$D$4,IF(AND(I183=INCERTEZA!$B$5,J183=INCERTEZA!$C$5),INCERTEZA!$D$5,IF(AND(I183=INCERTEZA!$B$6,J183=INCERTEZA!$C$6),INCERTEZA!$D$6,IF(AND(I183=INCERTEZA!$B$7,J183=INCERTEZA!$C$7),INCERTEZA!$D$7,IF(AND(I183=INCERTEZA!$B$8,J183=INCERTEZA!$C$8),INCERTEZA!$D$8,IF(AND(I183=INCERTEZA!$B$9,J183=INCERTEZA!$C$9),INCERTEZA!$D$9,IF(AND(I183=INCERTEZA!$B$10,J183=INCERTEZA!$C$10),INCERTEZA!$D$10,IF(AND(I183=INCERTEZA!$B$11,J183=INCERTEZA!$C$11),INCERTEZA!$D$11,IF(AND(I183=INCERTEZA!$B$12,J183=INCERTEZA!$C$12),INCERTEZA!$D$12,IF(AND(I183=INCERTEZA!$B$13,J183=INCERTEZA!$C$13),INCERTEZA!$D$13,IF(AND(I183=INCERTEZA!$B$14,J183=INCERTEZA!$C$14),INCERTEZA!$D$14,IF(AND(I183=INCERTEZA!$B$15,J183=INCERTEZA!$C$15),INCERTEZA!$D$15,IF(AND(I183=INCERTEZA!$B$16,J183=INCERTEZA!$C$16),INCERTEZA!$D$16,IF(AND(I183=INCERTEZA!$B$17,J183=INCERTEZA!$C$17),INCERTEZA!$D$17,"-"))))))))))))))) -> - | L183: =AEP!CX188 -> 0 | M183: =AEP!CO188 -> 0 | N183: =IF(AND(L183=monitoramento!$C$4,M183=monitoramento!$D$4),monitoramento!$E$4,IF(AND(L183=monitoramento!$C$5,M183=monitoramento!$D$5),monitoramento!$E$5,IF(AND(L183=monitoramento!$C$6,M183=monitoramento!$D$6),monitoramento!$E$6,IF(AND(L183=monitoramento!$C$7,M183=monitoramento!$D$7),monitoramento!$E$7,IF(AND(L183=monitoramento!$C$8,M183=monitoramento!$D$8),monitoramento!$E$8,IF(AND(L183=monitoramento!$C$9,M183=monitoramento!$D$9),monitoramento!$E$9,IF(AND(L183=monitoramento!$C$10,M183=monitoramento!$D$10),monitoramento!$E$10,IF(AND(L183=monitoramento!$C$11,M183=monitoramento!$D$11),monitoramento!$E$11,IF(AND(L183=monitoramento!$C$12,M183=monitoramento!$D$12),monitoramento!$E$12,IF(AND(L183=monitoramento!$C$13,M183=monitoramento!$D$13),monitoramento!$E$13,IF(AND(L183=monitoramento!$C$14,M183=monitoramento!$D$14),monitoramento!$E$14,IF(AND(L183=monitoramento!$C$15,M183=monitoramento!$D$15),monitoramento!$E$15,IF(AND(L183=monitoramento!$C$16,M183=monitoramento!$D$16),monitoramento!$E$16,IF(AND(L183=monitoramento!$C$17,M183=monitoramento!$D$17),monitoramento!$E$17,IF(AND(L183=monitoramento!$C$18,M183=monitoramento!$D$18),monitoramento!$E$18,IF(AND(L183=monitoramento!$C$19,M183=monitoramento!$D$19),monitoramento!$E$19)))))))))))))))) -> FALSE

Sheet Planilha5
C3: PROBABILIDADE | D3: CARACTERÍSTICA | E3: MONITORAMENTO
B4: A | C4: PROVÁVEL | D4: REVERSÍVEL LEVE | E4: ANUAL (P1)
B5: B | C5: PROVÁVEL | D5: REVERSÍVEL SEVERO | E5: MONITORAR APÓS ADOTAR MEDIDAS DE CONTROLE (P1)
B6: C | C6: PROVÁVEL | D6: IRREVERSÍVEL SEVERO | E6: MONITORAR APÓS ADOTAR MEDIDAS DE CONTROLE (P1)
B7: D | C7: PROVÁVEL | D7: FATAL OU INCAPACITANTE | E7: MONITORAR APÓS ADOTAR MEDIDAS DE CONTROLE (P1)
B8: E | C8: POUCO PROVÁVEL | D8: REVERSÍVEL LEVE | E8: ANUAL (P2)
B9: F | C9: POUCO PROVÁVEL | D9: REVERSÍVEL SEVERO | E9: ANUAL (P2)
B10: G | C10: POUCO PROVÁVEL | D10: IRREVERSÍVEL SEVERO | E10: SEMESTRAL (P1)
B11: H | C11: POUCO PROVÁVEL | D11: FATAL OU INCAPACITANTE | E11: TRIMESTRAL (P1)
B12: I | C12: IMPROVÁVEL | D12: REVERSÍVEL LEVE | E12: MONITORAMENTO PERIÓDICO NÃO NECESSÁRIO
B13: J | C13: IMPROVÁVEL | D13: REVERSÍVEL SEVERO | E13: MONITORAMENTO PERIÓDICO NÃO NECESSÁRIO
B14: K | C14: IMPROVÁVEL | D14: IRREVERSÍVEL SEVERO | E14: ANUAL (P1)
B15: L | C15: IMPROVÁVEL | D15: FATAL OU INCAPACITANTE | E15: SEMESTRAL (P1)
... B19: P | C19: ALTAMENTE IMPROVÁVEL | D19: FATAL OU INCAPACITANTE | E19: ANUAL (P1)
C22: ALTAMENTE IMPROVÁVEL | D22: FATAL OU INCAPACITANTE | E22: =IF(AND(C22=$C$4,D22=$D$4),$E$4,IF(AND(C22=$C$5,D22=$D$5),$E$5,IF(AND(C22=$C$6,D22=$D$6),$E$6,IF(AND(C22=$C$7,D22=$D$7),$E$7,IF(AND(C22=$C$8,D22=$D$8),$E$8,IF(AND(C22=$C$9,D22=$D$9),$E$9,IF(AND(C22=$C$10,D22=$D$10),$E$10,IF(AND(C22=$C$11,D22=$D$11),$E$11,IF(AND(C22=$C$12,D22=$D$12),$E$12,IF(AND(C22=$C$13,D22=$D$13),$E$13,IF(AND(C22=$C$14,D22=$D$14),$E$14,IF(AND(C22=$C$15,D22=$D$15),$E$15,IF(AND(C22=$C$16,D22=$D$16),$E$16,IF(AND(C22=$C$17,D22=$D$17),$E$17,IF(AND(C22=$C$18,D22=$D$18),$E$18,IF(AND(C22=$C$19,D22=$D$19),$E$19)))))))))))))))) -> ANUAL (P1)

Sheet Planilha11
A1: BIOMECÂNICOS | B1: MOBILIÁRIO_E_EQUIPAMENTOS | C1: ORGANIZACIONAIS | D1: AMBIENTAIS | E1: PSICOSSOCIAIS_E_COGNITIVOS
A2: Trabalho em posturas incômodas ou pouco confortáveis por longos períodos | B2: Posto de trabalho improvisado. | C2: Trabalho realizado sem pausas pré-definidas para descanso. | D2: Condições de trabalho com níveis de pressão sonora fora dos parâmetros de conforto. | E2: Excesso de situações de estresse.
A3: Postura sentada por longos períodos. | B3: Mobiliário sem meios de regulagem de ajuste. | C3: Necessidade de manter ritmos intensos de trabalho. | D3: Condições de trabalho com índice de temperatura efetiva fora dos parâmetros de conforto. | E3: Situações de sobrecarga de trabalho mental.
A4: Postura de pé por longos períodos. | B4: Equipamentos e/ou máquinas sem meios de regulagem de ajuste ou sem condições de uso. | C4: Trabalho com necessidade de variação de turnos | D4: Condições de trabalho com velocidade do ar fora dos parâmetros de conforto. | E4: Exigência de alto nível de concentração, atenção e memória.
A5: Frequente deslocamento a pé durante a jornada de trabalho. | B5: Posto de trabalho não planejado/adaptado para a posição sentada. | C5: Monotonia. | D5: Condições de trabalho com umidade do ar fora dos parâmetros de conforto. | E5: Trabalho em condições de difícil comunicação.
A6: Trabalho com esforço físico intenso. | B6: Assento inadequado. | C6: Trabalho noturno. | D6: Condições de trabalho com Iluminação diurna inadequada. | E6: Excesso de conflitos hierárquicos no trabalho.
A7: Levantamento e transporte manual de cargas ou volumes. | B7: Encosto do assento inadequado ou ausente. | C7: Insuficiência de capacitação para execução da tarefa. | D7: Condições de trabalho com Iluminação noturna inadequada. | E7: Excesso de demandas emocionais/afetivas no trabalho.
